<?xml version="1.0" ?>
<!-- =================================================================================== -->
<!-- |    This document was autogenerated by xacro from ./sliping_robot_motor.xacro    | -->
<!-- |    EDITING THIS FILE BY HAND IS NOT RECOMMENDED                                 | -->
<!-- =================================================================================== -->
<robot name="sliping_robot_motor">
  <!-- Base link -->
  <link name="base_link">
    <inertial>
      <mass value="5.0"/>
      <origin xyz="0 0 0"/>
      <inertia ixx="0.25" ixy="0" ixz="0" iyy="0.25" iyz="0" izz="0.25"/>
    </inertial>
    <visual>
      <geometry>
        <box size="0.8 0.4 0.2"/>
      </geometry>
    </visual>
    <collision>
      <geometry>
        <box size="0.8 0.4 0.2"/>
      </geometry>
    </collision>
  </link>
  <link name="front_left_wheel">
    <inertial>
      <mass value="0.1"/>
      <origin xyz="0 0 0"/>
      <inertia ixx="0.0007" ixy="0" ixz="0" iyy="0.00013" iyz="0" izz="0.0007"/>
    </inertial>
    <visual>
      <geometry>
        <cylinder length="0.02" radius="0.05"/>
      </geometry>
      <origin rpy="-1.5708 0 0"/>
    </visual>
    <collision>
      <geometry>
        <cylinder length="0.02" radius="0.05"/>
      </geometry>
      <origin rpy="-1.5708 0 0"/>
    </collision>
  </link>
  <joint name="front_left_joint" type="continuous">
    <parent link="base_link"/>
    <child link="front_left_wheel"/>
    <origin rpy="0 0 0" xyz="0.15 0.2 0.05"/>
    <axis xyz="0 0 1"/>
    <limit effort="100" velocity="100"/>
    <dynamics damping="0.005" friction="0.01"/>
  </joint>
  <transmission name="front_left_trans">
    <type>transmission_interface/SimpleTransmission</type>
    <actuator name="front_left_motor">
      <mechanicalReduction>1</mechanicalReduction>
    </actuator>
    <joint name="front_left_joint">
      <hardwareInterface>EffortJointInterface</hardwareInterface>
    </joint>
  </transmission>
  <link name="front_right_wheel">
    <inertial>
      <mass value="0.1"/>
      <origin xyz="0 0 0"/>
      <inertia ixx="0.0007" ixy="0" ixz="0" iyy="0.00013" iyz="0" izz="0.0007"/>
    </inertial>
    <visual>
      <geometry>
        <cylinder length="0.02" radius="0.05"/>
      </geometry>
      <origin rpy="-1.5708 0 0"/>
    </visual>
    <collision>
      <geometry>
        <cylinder length="0.02" radius="0.05"/>
      </geometry>
      <origin rpy="-1.5708 0 0"/>
    </collision>
  </link>
  <joint name="front_right_joint" type="continuous">
    <parent link="base_link"/>
    <child link="front_right_wheel"/>
    <origin rpy="0 0 0" xyz="0.15 -0.2 0.05"/>
    <axis xyz="0 0 1"/>
    <limit effort="100" velocity="100"/>
    <dynamics damping="0.005" friction="0.01"/>
  </joint>
  <transmission name="front_right_trans">
    <type>transmission_interface/SimpleTransmission</type>
    <actuator name="front_right_motor">
      <mechanicalReduction>1</mechanicalReduction>
    </actuator>
    <joint name="front_right_joint">
      <hardwareInterface>EffortJointInterface</hardwareInterface>
    </joint>
  </transmission>
  <link name="rear_left_wheel">
    <inertial>
      <mass value="0.1"/>
      <origin xyz="0 0 0"/>
      <inertia ixx="0.0007" ixy="0" ixz="0" iyy="0.00013" iyz="0" izz="0.0007"/>
    </inertial>
    <visual>
      <geometry>
        <cylinder length="0.02" radius="0.05"/>
      </geometry>
      <origin rpy="-1.5708 0 0"/>
    </visual>
    <collision>
      <geometry>
        <cylinder length="0.02" radius="0.05"/>
      </geometry>
      <origin rpy="-1.5708 0 0"/>
    </collision>
  </link>
  <joint name="rear_left_joint" type="continuous">
    <parent link="base_link"/>
    <child link="rear_left_wheel"/>
    <origin rpy="0 0 0" xyz="-0.35 0.2 0.05"/>
    <axis xyz="0 0 1"/>
    <limit effort="100" velocity="100"/>
    <dynamics damping="0.005" friction="0.01"/>
  </joint>
  <transmission name="rear_left_trans">
    <type>transmission_interface/SimpleTransmission</type>
    <actuator name="rear_left_motor">
      <mechanicalReduction>1</mechanicalReduction>
    </actuator>
    <joint name="rear_left_joint">
      <hardwareInterface>EffortJointInterface</hardwareInterface>
    </joint>
  </transmission>
  <link name="rear_right_wheel">
    <inertial>
      <mass value="0.1"/>
      <origin xyz="0 0 0"/>
      <inertia ixx="0.0007" ixy="0" ixz="0" iyy="0.00013" iyz="0" izz="0.0007"/>
    </inertial>
    <visual>
      <geometry>
        <cylinder length="0.02" radius="0.05"/>
      </geometry>
      <origin rpy="-1.5708 0 0"/>
    </visual>
    <collision>
      <geometry>
        <cylinder length="0.02" radius="0.05"/>
      </geometry>
      <origin rpy="-1.5708 0 0"/>
    </collision>
  </link>
  <joint name="rear_right_joint" type="continuous">
    <parent link="base_link"/>
    <child link="rear_right_wheel"/>
    <origin rpy="0 0 0" xyz="-0.35 -0.2 0.05"/>
    <axis xyz="0 0 1"/>
    <limit effort="100" velocity="100"/>
    <dynamics damping="0.005" friction="0.01"/>
  </joint>
  <transmission name="rear_right_trans">
    <type>transmission_interface/SimpleTransmission</type>
    <actuator name="rear_right_motor">
      <mechanicalReduction>1</mechanicalReduction>
    </actuator>
    <joint name="rear_right_joint">
      <hardwareInterface>EffortJointInterface</hardwareInterface>
    </joint>
  </transmission>
</robot>

